Workbook

Sheet Listas
A1: Setores | B1: Status | C1: Prioridades | D1: Familias | E1: Operacoes | F1: Unidades | G1: Turnos | H1: Uso
A2: CORTE | B2: Planejado | C2: P1 - Atrasado/24h | D2: Produto simples | E2: SECCIONADORA 10 | F2: peça | G2: 1 | H2: Obrigatório
A3: USINAGEM | B3: Programado | C3: P2 - 48h | D3: Produto com acabamento | E3: SECCIONADORA 11 | F3: un | H3: Opcional
A4: SERRA FITA | B4: Em produção | C4: P3 - Semana | D4: Produto usinado | E4: SERRA FITA | F4: par | H4: Calculado
A5: PADE | B5: Parado | C5: P4 - Normal | D5: Produto montado | E5: PADE VELOX | F5: kg | H5: Manual
A6: CNC | B6: Concluído | D6: Produto especial | E6: CNC NESTING | F6: m
A7: PU | B7: Atrasado | D7: Reposição | E7: COPIADORA | F7: m²
A8: FURADEIRA | B8: Cancelado | D8: Protótipo | E8: USINAGEM | F8: lote
A9: COLADEIRA DE BORDO | D9: Embalagem | E9: MONTAGEM DE TAMPOS | F9: caixas
A10: COLADEIRA MANUAL | E10: PU
A11: COPIADORA | E11: FURADEIRA 20
A12: MONTAGEM DE TAMPOS | E12: FURADEIRA 21
A13: UV | E13: FURADEIRA 22
A14: MONTAGEM DE CADEIRAS | E14: FURADEIRA 65
A15: COLA DE ESPUMA | E15: COLADEIRA 23
A16: TAPEÇARIA | E16: COLADEIRA 122
A17: EMBALAGEM | E17: COLADEIRA 126
A18: COLAGEM DE VIDROS | E18: COLADEIRA 24
A19: CARTONAGEM | E19: UV 54
E20: MONTAGEM DE CADEIRAS (3 FUNC)
E21: COLA DE ESPUMA (2FUNC)
E22: TAPEÇARIA (6 FUNC)
E23: CARTONAGEM
E24: EMBALAGEM 91

Sheet 01_Cad_Pecas
A1: Produto/Equipamento | B1: Codigo Produto | C1: Familia | D1: Codigo Peca | E1: Descricao da Peca | F1: Qtde por Produto | G1: Unidade | H1: Tempo Setup Padrao (min) | I1: Tempo Unit Padrao (min/peca) | J1: Setor Inicial
A2: CARTONAGEM | B2: 91014030 | C2: Embalagem | D2: 91014030 | E2: EMB. CABECEIRAS 01 (X2) (440X2800) | F2: 1 | G2: caixas | H2: 8 | I2: 0.2 | J2: CARTONAGEM
A3: CARTONAGEM | B3: 912084232 | C3: Embalagem | D3: 912084232 | E3: EMB. ACESSORIOS - CAMA TORONTO 1,40 (410X320 | F3: 1 | G3: caixas | H3: 8 | I3: 0.2 | J3: CARTONAGEM
A4: CARTONAGEM | B4: 200610130 | C4: Embalagem | D4: 200610130 | E4: EMB. MESA JADE PES (783X218X83) | F4: 1 | G4: caixas | H4: 8 | I4: 0.2 | J4: CARTONAGEM
A5: CARTONAGEM | B5: 200610230 | C5: Embalagem | D5: 200610230 | E5: EMB. TRAVESSAS MESA JADE 1,36 (1340X83X78) | F5: 1 | G5: caixas | H5: 8 | I5: 0.2 | J5: CARTONAGEM
A6: CARTONAGEM | B6: 200611230 | C6: Embalagem | D6: 200611230 | E6: EMB. TRAVESSAS MESA JADE 1,60 (1445X83X80) | F6: 1 | G6: caixas | H6: 8 | I6: 0.2 | J6: CARTONAGEM
A7: CARTONAGEM | B7: 200611231 | C7: Embalagem | D7: 200611231 | E7: EMB. CAIXA ACESSORIOS MESA JADE 1,36 (190X80X | F7: 1 | G7: caixas | H7: 8 | I7: 0.2 | J7: CARTONAGEM
A8: CARTONAGEM | B8: 200612230 | C8: Embalagem | D8: 200612230 | E8: EMB. TRAVESSAS MESA JADE 1,80 (1581X83X81) | F8: 1 | G8: caixas | H8: 8 | I8: 0.2 | J8: CARTONAGEM
A9: CARTONAGEM | B9: 200620130 | C9: Embalagem | D9: 200620130 | E9: EMB. MESA AMETISTA PES (783X170X65) | F9: 1 | G9: caixas | H9: 8 | I9: 0.2 | J9: CARTONAGEM
A10: CARTONAGEM | B10: 200620230 | C10: Embalagem | D10: 200620230 | E10: EMB. TRAVESSAS MESA AMETISTA 1,36 (1399X83X96212 | F10: 1 | G10: caixas | H10: 8 | I10: 0.2 | J10: CARTONAGEM
A11: CARTONAGEM | B11: 200620231 | C11: Embalagem | D11: 200620231 | E11: EMB. CX. ACESSORIO MESA AMETISTA 1,36 (230X83 212 | F11: 1 | G11: caixas | H11: 8 | I11: 0.2 | J11: CARTONAGEM
A12: CARTONAGEM | B12: 200621230 | C12: Embalagem | D12: 200621230 | E12: EMB. TRAVESSAS MESA AMETISTA 1,60 (1545X83X96212 | F12: 1 | G12: caixas | H12: 8 | I12: 0.2 | J12: CARTONAGEM
A13: CARTONAGEM | B13: 200621231 | C13: Embalagem | D13: 200621231 | E13: EMB. CX. ACESSORIOS MESA AMETISTA 1,60 (160X8 212 | F13: 1 | G13: caixas | H13: 8 | I13: 0.2 | J13: CARTONAGEM
... A165: CARTONAGEM | B165: 91205733 | C165: Embalagem | D165: 91205733 | E165: EMB. ACESSORIOS CAMA LEON 1,95 (200X100X170) 212 | F165: 1 | G165: caixas | H165: 8 | I165: 0.2 | J165: CARTONAGEM
A166: CARTONAGEM | B166: 200200130MM | C166: Embalagem | D166: 200200130MM | E166: EMB. BASE DUBAI SEM IMPRESSAO (1190X370X57) 212 | F166: 1 | G166: caixas | H166: 8 | I166: 0.2 | J166: CARTONAGEM
A167: CARTONAGEM | B167: 200124130MM | C167: Embalagem | D167: 200124130MM | E167: EMB. MESA MIAMI 1,20 (1240X834X40) EMEN. S/ IMP. 212 | F167: 1 | G167: caixas | H167: 8 | I167: 0.2 | J167: CARTONAGEM
A168: CARTONAGEM | B168: 301240130MM | C168: Embalagem | D168: 301240130MM | E168: EMB. BASE DUBLIN 1,36 (880X774X64) EMND. S/ IMP. 212 | F168: 1 | G168: caixas | H168: 8 | I168: 0.2 | J168: CARTONAGEM
A169: CARTONAGEM | B169: 200520130MM | C169: Embalagem | D169: 200520130MM | E169: EMB. BASE MESA ATHENAS VL 01 (760X390X75) S/ IM212 | F169: 1 | G169: caixas | H169: 8 | I169: 0.2 | J169: CARTONAGEM
A170: CARTONAGEM | B170: 200613330 | C170: Embalagem | D170: 200613330 | E170: EMB. TRAVESSAS MESA JADE 2,00 (1763X83X81) | F170: 1 | G170: caixas | H170: 8 | I170: 0.2 | J170: CARTONAGEM
A171: CARTONAGEM | B171: 200131131 | C171: Embalagem | D171: 200131131 | E171: EMB. CANTONEIRA MIAMI/DAKAR (800X50) | F171: 1 | G171: caixas | H171: 8 | I171: 0.2 | J171: CARTONAGEM
A172: CARTONAGEM | B172: 20013112 | C172: Embalagem | D172: 20013112 | E172: EMB. CANTONEIRA MIAMI/DAKAR (900X50) | F172: 1 | G172: caixas | H172: 8 | I172: 0.2 | J172: CARTONAGEM
A173: CARTONAGEM | B173: 30003924 | C173: Embalagem | D173: 30003924 | E173: PAPELAO CAD TRENTO (360X260) (X3) | F173: 1 | G173: caixas | H173: 8 | I173: 0.2 | J173: CARTONAGEM
A174: CARTONAGEM | B174: 200536130 | C174: Embalagem | D174: 200536130 | E174: EMB. BASE MESA ATHENAS 1,6/1,8 VL 01 (1002X452X | F174: 1 | G174: caixas | H174: 8 | I174: 0.2 | J174: CARTONAGEM
A175: CARTONAGEM | B175: 20015111 | C175: Embalagem | D175: 20015111 | E175: EMB. MESA LISBOA 1,37 (789X472X84) | F175: 1 | G175: caixas | H175: 8 | I175: 0.2 | J175: CARTONAGEM
A176: CARTONAGEM | B176: 20015211 | C176: Embalagem | D176: 20015211 | E176: EMB. MESA LISBOA 1,60 (920X460X84) | F176: 1 | G176: caixas | H176: 8 | I176: 0.2 | J176: CARTONAGEM
A177: CARTONAGEM | B177: 20015311 | C177: Embalagem | D177: 20015311 | E177: EMB. MESA LISBOA 1,80 (1132X460X87) | F177: 1 | G177: caixas | H177: 8 | I177: 0.2 | J177: CARTONAGEM
A178: CARTONAGEM | B178: 20015011 | C178: Embalagem | D178: 20015011 | E178: EMB. MESA LISBOA 0,90X0,90 (802X472X54) | F178: 1 | G178: caixas | H178: 8 | I178: 0.2 | J178: CARTONAGEM
A179: CARTONAGEM | B179: 30003930 | C179: Embalagem | D179: 30003930 | E179: EMB. CADEIRAS TRENTO (1055X442X100) | F179: 1 | G179: caixas | H179: 8 | I179: 0.2 | J179: CARTONAGEM
A180: CARTONAGEM | B180: 30003932 | C180: Embalagem | D180: 30003932 | E180: EMB. CANTONEIRA CADEIRA TRENTO (502X500X72) | F180: 1 | G180: caixas | H180: 8 | I180: 0.2 | J180: CARTONAGEM
A181: CARTONAGEM | B181: 10050530 | C181: Embalagem | D181: 10050530 | E181: EMB. BAU MALAGA (1185X465X110) | F181: 1 | G181: caixas | H181: 8 | I181: 0.2 | J181: CARTONAGEM
... A548: COPIADORA | B548: 200303205 | C548: Produto usinado | D548: 200303205 | E548: TAMPO ENGROSSADO R100 C/ VIDRO 1360X900X40 1 | F548: 1 | G548: peça | H548: 2 | I548: 1.45 | J548: CORTE
A549: COPIADORA | B549: 20060011 | C549: Produto usinado | D549: 20060011 | F549: 1 | G549: peça | H549: 2 | I549: 1.45 | J549: CORTE
A550: SECCIONADORA 10 | B550: 30082501 | C550: Produto simples | D550: 30082501 | E550: PE MAIOR 740X120 (194)X18 MDF - MESA SIENA | F550: 1 | G550: peça | H550: 1.1 | I550: 0.09375 | J550: CORTE
A551: SECCIONADORA 10 | B551: 30082502 | C551: Produto simples | D551: 30082502 | E551: PE MENOR 740X100 (164)X18 MDF - MESA SIENA | F551: 1 | G551: peça | H551: 1.1 | I551: 0.09375 | J551: CORTE
A552: SECCIONADORA 10 | B552: 30082504 | C552: Produto simples | D552: 30082504 | E552: TRAVESSA LATERAL 810X120X15 MDF-MESA SIENA | F552: 1 | G552: peça | H552: 1.1 | I552: 0.09375 | J552: CORTE
A553: SECCIONADORA 10 | B553: 30082003 | C553: Produto simples | D553: 30082003 | E553: TRAV FRONTAL 780X120X15 MDF - MESA SIENA 0,90 1 | F553: 1 | G553: peça | H553: 1.1 | I553: 0.09375 | J553: CORTE
A554: SECCIONADORA 10 | B554: 30082203 | C554: Produto simples | D554: 30082203 | E554: TRAV FRONT 1080X120X15 MDF-MESA SIENA C/V1,2 1 | F554: 1 | G554: peça | H554: 1.1 | I554: 0.09375 | J554: CORTE
A555: SECCIONADORA 10 | B555: 30082503 | C555: Produto simples | D555: 30082503 | E555: TRAV FRONT 1480X120X15 MDF-MESA SIENA C/V1,6 1 | F555: 1 | G555: peça | H555: 1.1 | I555: 0.09375 | J555: CORTE
A556: SECCIONADORA 10 | B556: 30083002 | C556: Produto simples | D556: 30083002 | E556: (4) LAT BAS INTERNA 780X455X15 MDP-MES TRENTO1 | F556: 1 | G556: peça | H556: 1.1 | I556: 0.09375 | J556: CORTE
A557: SECCIONADORA 10 | B557: 30083501 | C557: Produto simples | D557: 30083501 | E557: LAT BAS INTERNA 780X910X15 MDP-MES FLOREN 1, 1 | F557: 1 | G557: peça | H557: 1.1 | I557: 0.09375 | J557: CORTE
...

Sheet 02_Cad_Maquinas
A1: Setor | B1: Maquina/Posto | C1: Responsavel | D1: Turnos/dia | E1: Horas por turno | F1: Horas disponiveis/dia | G1: Eficiencia planejada % | H1: Capacidade efetiva (min/dia) | I1: Setup medio (min)
A2: CORTE | B2: SECCIONADORA 10 | C2: GUSTAVO | D2: 1 | E2: 8.8 | F2: =IF(OR(D2="",E2=""),"",D2*E2) | G2: 0.9 | H2: =IF(OR(F2="",G2=""),"",F2*60*G2)
A3: CORTE | B3: SECCIONADORA 11 | C3: GUSTAVO | D3: 1 | E3: 8.8 | F3: =IF(OR(D3="",E3=""),"",D3*E3) | G3: 0.9 | H3: =IF(OR(F3="",G3=""),"",F3*60*G3)
A4: SERRA FITA | B4: SERRA FITA | C4: THIAGO | D4: 1 | E4: 8.8 | F4: =IF(OR(D4="",E4=""),"",D4*E4) | G4: 0.9 | H4: =IF(OR(F4="",G4=""),"",F4*60*G4)
A5: PADE VELOX | B5: PADE VELOX | C5: THIAGO | D5: 1 | E5: 8.8 | F5: =IF(OR(D5="",E5=""),"",D5*E5) | G5: 0.9 | H5: =IF(OR(F5="",G5=""),"",F5*60*G5)
A6: CNC NESTING | B6: CNC NESTING | C6: ANDERSON | D6: 1 | E6: 8.8 | F6: =IF(OR(D6="",E6=""),"",D6*E6) | G6: 0.96 | H6: =IF(OR(F6="",G6=""),"",F6*60*G6)
A7: COPIADORA | B7: COPIADORA | C7: ANDERSON | D7: 1 | E7: 8.8 | F7: =IF(OR(D7="",E7=""),"",D7*E7) | G7: 0.92 | H7: =IF(OR(F7="",G7=""),"",F7*60*G7)
A8: USINAGEM | B8: USINAGEM | C8: VAGNER | D8: 1 | E8: 8.8 | F8: =IF(OR(D8="",E8=""),"",D8*E8) | G8: 0.92 | H8: =IF(OR(F8="",G8=""),"",F8*60*G8)
A9: MONTAGEM DE TAMPOS | B9: MONTAGEM DE TAMPOS | C9: VAGNER | D9: 1 | E9: 8.8 | F9: =IF(OR(D9="",E9=""),"",D9*E9) | G9: 0.98 | H9: =IF(OR(F9="",G9=""),"",F9*60*G9)
A10: PU | B10: PU | C10: DAVID | D10: 1 | E10: 8.8 | F10: =IF(OR(D10="",E10=""),"",D10*E10) | G10: 0.95 | H10: =IF(OR(F10="",G10=""),"",F10*60*G10)
A11: FURADEIRA | B11: FURADEIRA 20 | C11: EDINILSON | D11: 1 | E11: 8.8 | F11: =IF(OR(D11="",E11=""),"",D11*E11) | G11: 0.8 | H11: =IF(OR(F11="",G11=""),"",F11*60*G11)
A12: FURADEIRA | B12: FURADEIRA 21 | C12: EDINILSON | D12: 1 | E12: 8.8 | F12: =IF(OR(D12="",E12=""),"",D12*E12) | G12: 0.8 | H12: =IF(OR(F12="",G12=""),"",F12*60*G12)
A13: FURADEIRA | B13: FURADEIRA 22 | C13: EDINILSON | D13: 1 | E13: 8.8 | F13: =IF(OR(D13="",E13=""),"",D13*E13) | G13: 0.8 | H13: =IF(OR(F13="",G13=""),"",F13*60*G13)
... A42: CNC NESTING | B42: CNC | C42: ANDERSON | D42: 1 | E42: 8.8 | F42: =IF(OR(D42="",E42=""),"",D42*E42) | G42: 0.96 | H42: =IF(OR(F42="",G42=""),"",F42*60*G42)
F43: =IF(OR(D43="",E43=""),"",D43*E43) | H43: =IF(OR(F43="",G43=""),"",F43*60*G43)
F44: =IF(OR(D44="",E44=""),"",D44*E44) | H44: =IF(OR(F44="",G44=""),"",F44*60*G44)
F45: =IF(OR(D45="",E45=""),"",D45*E45) | H45: =IF(OR(F45="",G45=""),"",F45*60*G45)
F46: =IF(OR(D46="",E46=""),"",D46*E46) | H46: =IF(OR(F46="",G46=""),"",F46*60*G46)
F47: =IF(OR(D47="",E47=""),"",D47*E47) | H47: =IF(OR(F47="",G47=""),"",F47*60*G47)
F48: =IF(OR(D48="",E48=""),"",D48*E48) | H48: =IF(OR(F48="",G48=""),"",F48*60*G48)
F49: =IF(OR(D49="",E49=""),"",D49*E49) | H49: =IF(OR(F49="",G49=""),"",F49*60*G49)
F50: =IF(OR(D50="",E50=""),"",D50*E50) | H50: =IF(OR(F50="",G50=""),"",F50*60*G50)
F51: =IF(OR(D51="",E51=""),"",D51*E51) | H51: =IF(OR(F51="",G51=""),"",F51*60*G51)
F52: =IF(OR(D52="",E52=""),"",D52*E52) | H52: =IF(OR(F52="",G52=""),"",F52*60*G52)
F53: =IF(OR(D53="",E53=""),"",D53*E53) | H53: =IF(OR(F53="",G53=""),"",F53*60*G53)
F54: =IF(OR(D54="",E54=""),"",D54*E54) | H54: =IF(OR(F54="",G54=""),"",F54*60*G54)
... F196: =IF(OR(D196="",E196=""),"",D196*E196) | H196: =IF(OR(F196="",G196=""),"",F196*60*G196)

Sheet 4_PROGRAMADO
A1: Data Entrega | B1: LOTE | C1: EQUIPAMENTO | D1: Total Peças Estimado | E1: Dias Atraso/Adiantamento | F1: Qtde Produzida | G1: Qtde em Aberto | H1: CHAVE_LOTE_EQUIPAMENTO
A2: =IF(OR($B2="",$C2=""),"",IFERROR(INDEX('5_ACOMPANHAMENTO'!$A$3:$A$4922,MATCH(1,INDEX(('5_ACOMPANHAMENTO'!$AD$3:$AD$4922=TRIM($C2&""))*('5_ACOMPANHAMENTO'!$AC$3:$AC$4922<>"")*((((I2<>"")*ISNUMBER(SEARCH("|"&I2&"|",'5_ACOMPANHAMENTO'!$AC$3:$AC$4922)))+((J2<>"")*ISNUMBER(SEARCH("|"&J2&"|",'5_ACOMPANHAMENTO'!$AC$3:$AC$4922)))+((K2<>"")*ISNUMBER(SEARCH("|"&K2&"|",'5_ACOMPANHAMENTO'!$AC$3:$AC$4922)))+((L2<>"")*ISNUMBER(SEARCH("|"&L2&"|",'5_ACOMPANHAMENTO'!$AC$3:$AC$4922)))+((M2<>"")*ISNUMBER(SEARCH("|"&M2&"|",'5_ACOMPANHAMENTO'!$AC$3:$AC$4922)))+((N2<>"")*ISNUMBER(SEARCH("|"&N2&"|",'5_ACOMPANHAMENTO'!$AC$3:$AC$4922)))+((O2<>"")*ISNUMBER(SEARCH("|"&O2&"|",'5_ACOMPANHAMENTO'!$AC$3:$AC$4922)))+((P2<>"")*ISNUMBER(SEARCH("|"&P2&"|",'5_ACOMPANHAMENTO'!$AC$3:$AC$4922)))+((Q2<>"")*ISNUMBER(SEARCH("|"&Q2&"|",'5_ACOMPANHAMENTO'!$AC$3:$AC$4922)))+((R2<>"")*ISNUMBER(SEARCH("|"&R2&"|",'5_ACOMPANHAMENTO'!$AC$3:$AC$4922)))+((S2<>"")*ISNUMBER(SEARCH("|"&S2&"|",'5_ACOMPANHAMENTO'!$AC$3:$AC$4922)))+((T2<>"")*ISNUMBER(SEARCH("|"&T2&"|",'5_ACOMPANHAMENTO'!$AC$3:$AC$4922)))+((U2<>"")*ISNUMBER(SEARCH("|"&U2&"|",'5_ACOMPANHAMENTO'!$AC$3:$AC$4922)))+((V2<>"")*ISNUMBER(SEARCH("|"&V2&"|",'5_ACOMPANHAMENTO'!$AC$3:$AC$4922)))+((W2<>"")*ISNUMBER(SEARCH("|"&W2&"|",'5_ACOMPANHAMENTO'!$AC$3:$AC$4922)))+((X2<>"")*ISNUMBER(SEARCH("|"&X2&"|",'5_ACOMPANHAMENTO'!$AC$3:$AC$4922)))+((Y2<>"")*ISNUMBER(SEARCH("|"&Y2&"|",'5_ACOMPANHAMENTO'!$AC$3:$AC$4922)))+((Z2<>"")*ISNUMBER(SEARCH("|"&Z2&"|",'5_ACOMPANHAMENTO'!$AC$3:$AC$4922)))+((AA2<>"")*ISNUMBER(SEARCH("|"&AA2&"|",'5_ACOMPANHAMENTO'!$AC$3:$AC$4922)))+((AB2<>"")*ISNUMBER(SEARCH("|"&AB2&"|",'5_ACOMPANHAMENTO'!$AC$3:$AC$4922))))>0),0),0)),"")) | B2: 10176 | C2: SECCIONADORA 10 | D2: =IF(OR($B2="",$C2=""),"",IFERROR(SUMPRODUCT(--(('5_ACOMPANHAMENTO'!$AD$3:$AD$4922=TRIM($C2&""))*('5_ACOMPANHAMENTO'!$AC$3:$AC$4922<>"")*((((I2<>"")*ISNUMBER(SEARCH("|"&I2&"|",'5_ACOMPANHAMENTO'!$AC$3:$AC$4922)))+((J2<>"")*ISNUMBER(SEARCH("|"&J2&"|",'5_ACOMPANHAMENTO'!$AC$3:$AC$4922)))+((K2<>"")*ISNUMBER(SEARCH("|"&K2&"|",'5_ACOMPANHAMENTO'!$AC$3:$AC$4922)))+((L2<>"")*ISNUMBER(SEARCH("|"&L2&"|",'5_ACOMPANHAMENTO'!$AC$3:$AC$4922)))+((M2<>"")*ISNUMBER(SEARCH("|"&M2&"|",'5_ACOMPANHAMENTO'!$AC$3:$AC$4922)))+((N2<>"")*ISNUMBER(SEARCH("|"&N2&"|",'5_ACOMPANHAMENTO'!$AC$3:$AC$4922)))+((O2<>"")*ISNUMBER(SEARCH("|"&O2&"|",'5_ACOMPANHAMENTO'!$AC$3:$AC$4922)))+((P2<>"")*ISNUMBER(SEARCH("|"&P2&"|",'5_ACOMPANHAMENTO'!$AC$3:$AC$4922)))+((Q2<>"")*ISNUMBER(SEARCH("|"&Q2&"|",'5_ACOMPANHAMENTO'!$AC$3:$AC$4922)))+((R2<>"")*ISNUMBER(SEARCH("|"&R2&"|",'5_ACOMPANHAMENTO'!$AC$3:$AC$4922)))+((S2<>"")*ISNUMBER(SEARCH("|"&S2&"|",'5_ACOMPANHAMENTO'!$AC$3:$AC$4922)))+((T2<>"")*ISNUMBER(SEARCH("|"&T2&"|",'5_ACOMPANHAMENTO'!$AC$3:$AC$4922)))+((U2<>"")*ISNUMBER(SEARCH("|"&U2&"|",'5_ACOMPANHAMENTO'!$AC$3:$AC$4922)))+((V2<>"")*ISNUMBER(SEARCH("|"&V2&"|",'5_ACOMPANHAMENTO'!$AC$3:$AC$4922)))+((W2<>"")*ISNUMBER(SEARCH("|"&W2&"|",'5_ACOMPANHAMENTO'!$AC$3:$AC$4922)))+((X2<>"")*ISNUMBER(SEARCH("|"&X2&"|",'5_ACOMPANHAMENTO'!$AC$3:$AC$4922)))+((Y2<>"")*ISNUMBER(SEARCH("|"&Y2&"|",'5_ACOMPANHAMENTO'!$AC$3:$AC$4922)))+((Z2<>"")*ISNUMBER(SEARCH("|"&Z2&"|",'5_ACOMPANHAMENTO'!$AC$3:$AC$4922)))+((AA2<>"")*ISNUMBER(SEARCH("|"&AA2&"|",'5_ACOMPANHAMENTO'!$AC$3:$AC$4922)))+((AB2<>"")*ISNUMBER(SEARCH("|"&AB2&"|",'5_ACOMPANHAMENTO'!$AC$3:$AC$4922))))>0)),'5_ACOMPANHAMENTO'!$J$3:$J$4922),0)) | E2: =IF(G2=0,"FINALIZADO",IF(TODAY()>A2,"ATRASADO "&TODAY()-A2&" DIAS","ADIANTADO "&A2-TODAY()&" DIAS")) | F2: =IF(OR($B2="",$C2=""),"",IFERROR(SUMPRODUCT(--(('5_ACOMPANHAMENTO'!$AD$3:$AD$4922=TRIM($C2&""))*('5_ACOMPANHAMENTO'!$AC$3:$AC$4922<>"")*((((I2<>"")*ISNUMBER(SEARCH("|"&I2&"|",'5_ACOMPANHAMENTO'!$AC$3:$AC$4922)))+((J2<>"")*ISNUMBER(SEARCH("|"&J2&"|",'5_ACOMPANHAMENTO'!$AC$3:$AC$4922)))+((K2<>"")*ISNUMBER(SEARCH("|"&K2&"|",'5_ACOMPANHAMENTO'!$AC$3:$AC$4922)))+((L2<>"")*ISNUMBER(SEARCH("|"&L2&"|",'5_ACOMPANHAMENTO'!$AC$3:$AC$4922)))+((M2<>"")*ISNUMBER(SEARCH("|"&M2&"|",'5_ACOMPANHAMENTO'!$AC$3:$AC$4922)))+((N2<>"")*ISNUMBER(SEARCH("|"&N2&"|",'5_ACOMPANHAMENTO'!$AC$3:$AC$4922)))+((O2<>"")*ISNUMBER(SEARCH("|"&O2&"|",'5_ACOMPANHAMENTO'!$AC$3:$AC$4922)))+((P2<>"")*ISNUMBER(SEARCH("|"&P2&"|",'5_ACOMPANHAMENTO'!$AC$3:$AC$4922)))+((Q2<>"")*ISNUMBER(SEARCH("|"&Q2&"|",'5_ACOMPANHAMENTO'!$AC$3:$AC$4922)))+((R2<>"")*ISNUMBER(SEARCH("|"&R2&"|",'5_ACOMPANHAMENTO'!$AC$3:$AC$4922)))+((S2<>"")*ISNUMBER(SEARCH("|"&S2&"|",'5_ACOMPANHAMENTO'!$AC$3:$AC$4922)))+((T2<>"")*ISNUMBER(SEARCH("|"&T2&"|",'5_ACOMPANHAMENTO'!$AC$3:$AC$4922)))+((U2<>"")*ISNUMBER(SEARCH("|"&U2&"|",'5_ACOMPANHAMENTO'!$AC$3:$AC$4922)))+((V2<>"")*ISNUMBER(SEARCH("|"&V2&"|",'5_ACOMPANHAMENTO'!$AC$3:$AC$4922)))+((W2<>"")*ISNUMBER(SEARCH("|"&W2&"|",'5_ACOMPANHAMENTO'!$AC$3:$AC$4922)))+((X2<>"")*ISNUMBER(SEARCH("|"&X2&"|",'5_ACOMPANHAMENTO'!$AC$3:$AC$4922)))+((Y2<>"")*ISNUMBER(SEARCH("|"&Y2&"|",'5_ACOMPANHAMENTO'!$AC$3:$AC$4922)))+((Z2<>"")*ISNUMBER(SEARCH("|"&Z2&"|",'5_ACOMPANHAMENTO'!$AC$3:$AC$4922)))+((AA2<>"")*ISNUMBER(SEARCH("|"&AA2&"|",'5_ACOMPANHAMENTO'!$AC$3:$AC$4922)))+((AB2<>"")*ISNUMBER(SEARCH("|"&AB2&"|",'5_ACOMPANHAMENTO'!$AC$3:$AC$4922))))>0)),'5_ACOMPANHAMENTO'!$O$3:$O$4922),0)) | G2: =IF(OR($B2="",$C2=""),"",D2-F2) | H2: =IF(OR($B2="",$C2=""),"",TRIM($B2&"")&"|"&TRIM($C2&"")) | I2: =IF($B2="","",TRIM(MID(SUBSTITUTE(TRIM(SUBSTITUTE(SUBSTITUTE(SUBSTITUTE(SUBSTITUTE(SUBSTITUTE(SUBSTITUTE(SUBSTITUTE(SUBSTITUTE(SUBSTITUTE(SUBSTITUTE(SUBSTITUTE(SUBSTITUTE(SUBSTITUTE(SUBSTITUTE(TRIM($B2&""),CHAR(10)," "),CHAR(13)," "),"."," "),";"," "),","," "),"/"," "),"+"," "),"-"," ")," "," ")," "," ")," "," ")," "," ")," "," ")," "," "))," ",REPT(" ",99)),1,99))) | J2: =IF($B2="","",TRIM(MID(SUBSTITUTE(TRIM(SUBSTITUTE(SUBSTITUTE(SUBSTITUTE(SUBSTITUTE(SUBSTITUTE(SUBSTITUTE(SUBSTITUTE(SUBSTITUTE(SUBSTITUTE(SUBSTITUTE(SUBSTITUTE(SUBSTITUTE(SUBSTITUTE(SUBSTITUTE(TRIM($B2&""),CHAR(10)," "),CHAR(13)," "),"."," "),";"," "),","," "),"/"," "),"+"," "),"-"," ")," "," ")," "," ")," "," ")," "," ")," "," ")," "," "))," ",REPT(" ",99)),100,99))) | K2: =IF($B2="","",TRIM(MID(SUBSTITUTE(TRIM(SUBSTITUTE(SUBSTITUTE(SUBSTITUTE(SUBSTITUTE(SUBSTITUTE(SUBSTITUTE(SUBSTITUTE(SUBSTITUTE(SUBSTITUTE(SUBSTITUTE(SUBSTITUTE(SUBSTITUTE(SUBSTITUTE(SUBSTITUTE(TRIM($B2&""),CHAR(10)," "),CHAR(13)," "),"."," "),";"," "),","," "),"/"," "),"+"," "),"-"," ")," "," ")," "," ")," "," ")," "," ")," "," ")," "," "))," ",REPT(" ",99)),199,99))) | L2: =IF($B2="","",TRIM(MID(SUBSTITUTE(TRIM(SUBSTITUTE(SUBSTITUTE(SUBSTITUTE(SUBSTITUTE(SUBSTITUTE(SUBSTITUTE(SUBSTITUTE(SUBSTITUTE(SUBSTITUTE(SUBSTITUTE(SUBSTITUTE(SUBSTITUTE(SUBSTITUTE(SUBSTITUTE(TRIM($B2&""),CHAR(10)," "),CHAR(13)," "),"."," "),";"," "),","," "),"/"," "),"+"," "),"-"," ")," "," ")," "," ")," "," ")," "," ")," "," ")," "," "))," ",REPT(" ",99)),298,99))) | M2: =IF($B2="","",TRIM(MID(SUBSTITUTE(TRIM(SUBSTITUTE(SUBSTITUTE(SUBSTITUTE(SUBSTITUTE(SUBSTITUTE(SUBSTITUTE(SUBSTITUTE(SUBSTITUTE(SUBSTITUTE(SUBSTITUTE(SUBSTITUTE(SUBSTITUTE(SUBSTITUTE(SUBSTITUTE(TRIM($B2&""),CHAR(10)," "),CHAR(13)," "),"."," "),";"," "),","," "),"/"," "),"+"," "),"-"," ")," "," ")," "," ")," "," ")," "," ")," "," ")," "," "))," ",REPT(" ",99)),397,99))) | N2: =IF($B2="","",TRIM(MID(SUBSTITUTE(TRIM(SUBSTITUTE(SUBSTITUTE(SUBSTITUTE(SUBSTITUTE(SUBSTITUTE(SUBSTITUTE(SUBSTITUTE(SUBSTITUTE(SUBSTITUTE(SUBSTITUTE(SUBSTITUTE(SUBSTITUTE(SUBSTITUTE(SUBSTITUTE(TRIM($B2&""),CHAR(10)," "),CHAR(13)," "),"."," "),";"," "),","," "),"/"," "),"+"," "),"-"," ")," "," ")," "," ")," "," ")," "," ")," "," ")," "," "))," ",REPT(" ",99)),496,99))) | O2: =IF($B2="","",TRIM(MID(SUBSTITUTE(TRIM(SUBSTITUTE(SUBSTITUTE(SUBSTITUTE(SUBSTITUTE(SUBSTITUTE(SUBSTITUTE(SUBSTITUTE(SUBSTITUTE(SUBSTITUTE(SUBSTITUTE(SUBSTITUTE(SUBSTITUTE(SUBSTITUTE(SUBSTITUTE(TRIM($B2&""),CHAR(10)," "),CHAR(13)," "),"."," "),";"," "),","," "),"/"," "),"+"," "),"-"," ")," "," ")," "," ")," "," ")," "," ")," "," ")," "," "))," ",REPT(" ",99)),595,99))) | P2: =IF($B2="","",TRIM(MID(SUBSTITUTE(TRIM(SUBSTITUTE(SUBSTITUTE(SUBSTITUTE(SUBSTITUTE(SUBSTITUTE(SUBSTITUTE(SUBSTITUTE(SUBSTITUTE(SUBSTITUTE(SUBSTITUTE(SUBSTITUTE(SUBSTITUTE(SUBSTITUTE(SUBSTITUTE(TRIM($B2&""),CHAR(10)," "),CHAR(13)," "),"."," "),";"," "),","," "),"/"," "),"+"," "),"-"," ")," "," ")," "," ")," "," ")," "," ")," "," ")," "," "))," ",REPT(" ",99)),694,99))) | Q2: =IF($B2="","",TRIM(MID(SUBSTITUTE(TRIM(SUBSTITUTE(SUBSTITUTE(SUBSTITUTE(SUBSTITUTE(SUBSTITUTE(SUBSTITUTE(SUBSTITUTE(SUBSTITUTE(SUBSTITUTE(SUBSTITUTE(SUBSTITUTE(SUBSTITUTE(SUBSTITUTE(SUBSTITUTE(TRIM($B2&""),CHAR(10)," "),CHAR(13)," "),"."," "),";"," "),","," "),"/"," "),"+"," "),"-"," ")," "," ")," "," ")," "," ")," "," ")," "," ")," "," "))," ",REPT(" ",99)),793,99))) | R2: =IF($B2="","",TRIM(MID(SUBSTITUTE(TRIM(SUBSTITUTE(SUBSTITUTE(SUBSTITUTE(SUBSTITUTE(SUBSTITUTE(SUBSTITUTE(SUBSTITUTE(SUBSTITUTE(SUBSTITUTE(SUBSTITUTE(SUBSTITUTE(SUBSTITUTE(SUBSTITUTE(SUBSTITUTE(TRIM($B2&""),CHAR(10)," "),CHAR(13)," "),"."," "),";"," "),","," "),"/"," "),"+"," "),"-"," ")," "," ")," "," ")," "," ")," "," ")," "," ")," "," "))," ",REPT(" ",99)),892,99))) | S2: =IF($B2="","",TRIM(MID(SUBSTITUTE(TRIM(SUBSTITUTE(SUBSTITUTE(SUBSTITUTE(SUBSTITUTE(SUBSTITUTE(SUBSTITUTE(SUBSTITUTE(SUBSTITUTE(SUBSTITUTE(SUBSTITUTE(SUBSTITUTE(SUBSTITUTE(SUBSTITUTE(SUBSTITUTE(TRIM($B2&""),CHAR(10)," "),CHAR(13)," "),"."," "),";"," "),","," "),"/"," "),"+"," "),"-"," ")," "," ")," "," ")," "," ")," "," ")," "," ")," "," "))," ",REPT(" ",99)),991,99))) | T2: =IF($B2="","",TRIM(MID(SUBSTITUTE(TRIM(SUBSTITUTE(SUBSTITUTE(SUBSTITUTE(SUBSTITUTE(SUBSTITUTE(SUBSTITUTE(SUBSTITUTE(SUBSTITUTE(SUBSTITUTE(SUBSTITUTE(SUBSTITUTE(SUBSTITUTE(SUBSTITUTE(SUBSTITUTE(TRIM($B2&""),CHAR(10)," "),CHAR(13)," "),"."," "),";"," "),","," "),"/"," "),"+"," "),"-"," ")," "," ")," "," ")," "," ")," "," ")," "," ")," "," "))," ",REPT(" ",99)),1090,99))) | U2: =IF($B2="","",TRIM(MID(SUBSTITUTE(TRIM(SUBSTITUTE(SUBSTITUTE(SUBSTITUTE(SUBSTITUTE(SUBSTITUTE(SUBSTITUTE(SUBSTITUTE(SUBSTITUTE(SUBSTITUTE(SUBSTITUTE(SUBSTITUTE(SUBSTITUTE(SUBSTITUTE(SUBSTITUTE(TRIM($B2&""),CHAR(10)," "),CHAR(13)," "),"."," "),";"," "),","," "),"/"," "),"+"," "),"-"," ")," "," ")," "," ")," "," ")," "," ")," "," ")," "," "))," ",REPT(" ",99)),1189,99))) | V2: =IF($B2="","",TRIM(MID(SUBSTITUTE(TRIM(SUBSTITUTE(SUBSTITUTE(SUBSTITUTE(SUBSTITUTE(SUBSTITUTE(SUBSTITUTE(SUBSTITUTE(SUBSTITUTE(SUBSTITUTE(SUBSTITUTE(SUBSTITUTE(SUBSTITUTE(SUBSTITUTE(SUBSTITUTE(TRIM($B2&""),CHAR(10)," "),CHAR(13)," "),"."," "),";"," "),","," "),"/"," "),"+"," "),"-"," ")," "," ")," "," ")," "," ")," "," ")," "," ")," "," "))," ",REPT(" ",99)),1288,99))) | W2: =IF($B2="","",TRIM(MID(SUBSTITUTE(TRIM(SUBSTITUTE(SUBSTITUTE(SUBSTITUTE(SUBSTITUTE(SUBSTITUTE(SUBSTITUTE(SUBSTITUTE(SUBSTITUTE(SUBSTITUTE(SUBSTITUTE(SUBSTITUTE(SUBSTITUTE(SUBSTITUTE(SUBSTITUTE(TRIM($B2&""),CHAR(10)," "),CHAR(13)," "),"."," "),";"," "),","," "),"/"," "),"+"," "),"-"," ")," "," ")," "," ")," "," ")," "," ")," "," ")," "," "))," ",REPT(" ",99)),1387,99))) | X2: =IF($B2="","",TRIM(MID(SUBSTITUTE(TRIM(SUBSTITUTE(SUBSTITUTE(SUBSTITUTE(SUBSTITUTE(SUBSTITUTE(SUBSTITUTE(SUBSTITUTE(SUBSTITUTE(SUBSTITUTE(SUBSTITUTE(SUBSTITUTE(SUBSTITUTE(SUBSTITUTE(SUBSTITUTE(TRIM($B2&""),CHAR(10)," "),CHAR(13)," "),"."," "),";"," "),","," "),"/"," "),"+"," "),"-"," ")," "," ")," "," ")," "," ")," "," ")," "," ")," "," "))," ",REPT(" ",99)),1486,99))) | Y2: =IF($B2="","",TRIM(MID(SUBSTITUTE(TRIM(SUBSTITUTE(SUBSTITUTE(SUBSTITUTE(SUBSTITUTE(SUBSTITUTE(SUBSTITUTE(SUBSTITUTE(SUBSTITUTE(SUBSTITUTE(SUBSTITUTE(SUBSTITUTE(SUBSTITUTE(SUBSTITUTE(SUBSTITUTE(TRIM($B2&""),CHAR(10)," "),CHAR(13)," "),"."," "),";"," "),","," "),"/"," "),"+"," "),"-"," ")," "," ")," "," ")," "," ")," "," ")," "," ")," "," "))," ",REPT(" ",99)),1585,99))) | Z2: =IF($B2="","",TRIM(MID(SUBSTITUTE(TRIM(SUBSTITUTE(SUBSTITUTE(SUBSTITUTE(SUBSTITUTE(SUBSTITUTE(SUBSTITUTE(SUBSTITUTE(SUBSTITUTE(SUBSTITUTE(SUBSTITUTE(SUBSTITUTE(SUBSTITUTE(SUBSTITUTE(SUBSTITUTE(TRIM($B2&""),CHAR(10)," "),CHAR(13)," "),"."," "),";"," "),","," "),"/"," "),"+"," "),"-"," ")," "," ")," "," ")," "," ")," "," ")," "," ")," "," "))," ",REPT(" ",99)),1684,99))) | AA2: =IF($B2="","",TRIM(MID(SUBSTITUTE(TRIM(SUBSTITUTE(SUBSTITUTE(SUBSTITUTE(SUBSTITUTE(SUBSTITUTE(SUBSTITUTE(SUBSTITUTE(SUBSTITUTE(SUBSTITUTE(SUBSTITUTE(SUBSTITUTE(SUBSTITUTE(SUBSTITUTE(SUBSTITUTE(TRIM($B2&""),CHAR(10)," "),CHAR(13)," "),"."," "),";"," "),","," "),"/"," "),"+"," "),"-"," ")," "," ")," "," ")," "," ")," "," ")," "," ")," "," "))," ",REPT(" ",99)),1783,99))) | AB2: =IF($B2="","",TRIM(MID(SUBSTITUTE(TRIM(SUBSTITUTE(SUBSTITUTE(SUBSTITUTE(SUBSTITUTE(SUBSTITUTE(SUBSTITUTE(SUBSTITUTE(SUBSTITUTE(SUBSTITUTE(SUBSTITUTE(SUBSTITUTE(SUBSTITUTE(SUBSTITUTE(SUBSTITUTE(TRIM($B2&""),CHAR(10)," "),CHAR(13)," "),"."," "),";"," "),","," "),"/"," "),"+"," "),"-"," ")," "," ")," "," ")," "," ")," "," ")," "," ")," "," "))," ",REPT(" ",99)),1882,99)))
A3: =IF(OR($B3="",$C3=""),"",IFERROR(INDEX('5_ACOMPANHAMENTO'!$A$3:$A$4922,MATCH(1,INDEX(('5_ACOMPANHAMENTO'!$AD$3:$AD$4922=TRIM($C3&""))*('5_ACOMPANHAMENTO'!$AC$3:$AC$4922<>"")*((((I3<>"")*ISNUMBER(SEARCH("|"&I3&"|",'5_ACOMPANHAMENTO'!$AC$3:$AC$4922)))+((J3<>"")*ISNUMBER(SEARCH("|"&J3&"|",'5_ACOMPANHAMENTO'!$AC$3:$AC$4922)))+((K3<>"")*ISNUMBER(SEARCH("|"&K3&"|",'5_ACOMPANHAMENTO'!$AC$3:$AC$4922)))+((L3<>"")*ISNUMBER(SEARCH("|"&L3&"|",'5_ACOMPANHAMENTO'!$AC$3:$AC$4922)))+((M3<>"")*ISNUMBER(SEARCH("|"&M3&"|",'5_ACOMPANHAMENTO'!$AC$3:$AC$4922)))+((N3<>"")*ISNUMBER(SEARCH("|"&N3&"|",'5_ACOMPANHAMENTO'!$AC$3:$AC$4922)))+((O3<>"")*ISNUMBER(SEARCH("|"&O3&"|",'5_ACOMPANHAMENTO'!$AC$3:$AC$4922)))+((P3<>"")*ISNUMBER(SEARCH("|"&P3&"|",'5_ACOMPANHAMENTO'!$AC$3:$AC$4922)))+((Q3<>"")*ISNUMBER(SEARCH("|"&Q3&"|",'5_ACOMPANHAMENTO'!$AC$3:$AC$4922)))+((R3<>"")*ISNUMBER(SEARCH("|"&R3&"|",'5_ACOMPANHAMENTO'!$AC$3:$AC$4922)))+((S3<>"")*ISNUMBER(SEARCH("|"&S3&"|",'5_ACOMPANHAMENTO'!$AC$3:$AC$4922)))+((T3<>"")*ISNUMBER(SEARCH("|"&T3&"|",'5_ACOMPANHAMENTO'!$AC$3:$AC$4922)))+((U3<>"")*ISNUMBER(SEARCH("|"&U3&"|",'5_ACOMPANHAMENTO'!$AC$3:$AC$4922)))+((V3<>"")*ISNUMBER(SEARCH("|"&V3&"|",'5_ACOMPANHAMENTO'!$AC$3:$AC$4922)))+((W3<>"")*ISNUMBER(SEARCH("|"&W3&"|",'5_ACOMPANHAMENTO'!$AC$3:$AC$4922)))+((X3<>"")*ISNUMBER(SEARCH("|"&X3&"|",'5_ACOMPANHAMENTO'!$AC$3:$AC$4922)))+((Y3<>"")*ISNUMBER(SEARCH("|"&Y3&"|",'5_ACOMPANHAMENTO'!$AC$3:$AC$4922)))+((Z3<>"")*ISNUMBER(SEARCH("|"&Z3&"|",'5_ACOMPANHAMENTO'!$AC$3:$AC$4922)))+((AA3<>"")*ISNUMBER(SEARCH("|"&AA3&"|",'5_ACOMPANHAMENTO'!$AC$3:$AC$4922)))+((AB3<>"")*ISNUMBER(SEARCH("|"&AB3&"|",'5_ACOMPANHAMENTO'!$AC$3:$AC$4922))))>0),0),0)),"")) | B3: 10176 | C3: SECCIONADORA 11 | D3: =IF(OR($B3="",$C3=""),"",IFERROR(SUMPRODUCT(--(('5_ACOMPANHAMENTO'!$AD$3:$AD$4922=TRIM($C3&""))*('5_ACOMPANHAMENTO'!$AC$3:$AC$4922<>"")*((((I3<>"")*ISNUMBER(SEARCH("|"&I3&"|",'5_ACOMPANHAMENTO'!$AC$3:$AC$4922)))+((J3<>"")*ISNUMBER(SEARCH("|"&J3&"|",'5_ACOMPANHAMENTO'!$AC$3:$AC$4922)))+((K3<>"")*ISNUMBER(SEARCH("|"&K3&"|",'5_ACOMPANHAMENTO'!$AC$3:$AC$4922)))+((L3<>"")*ISNUMBER(SEARCH("|"&L3&"|",'5_ACOMPANHAMENTO'!$AC$3:$AC$4922)))+((M3<>"")*ISNUMBER(SEARCH("|"&M3&"|",'5_ACOMPANHAMENTO'!$AC$3:$AC$4922)))+((N3<>"")*ISNUMBER(SEARCH("|"&N3&"|",'5_ACOMPANHAMENTO'!$AC$3:$AC$4922)))+((O3<>"")*ISNUMBER(SEARCH("|"&O3&"|",'5_ACOMPANHAMENTO'!$AC$3:$AC$4922)))+((P3<>"")*ISNUMBER(SEARCH("|"&P3&"|",'5_ACOMPANHAMENTO'!$AC$3:$AC$4922)))+((Q3<>"")*ISNUMBER(SEARCH("|"&Q3&"|",'5_ACOMPANHAMENTO'!$AC$3:$AC$4922)))+((R3<>"")*ISNUMBER(SEARCH("|"&R3&"|",'5_ACOMPANHAMENTO'!$AC$3:$AC$4922)))+((S3<>"")*ISNUMBER(SEARCH("|"&S3&"|",'5_ACOMPANHAMENTO'!$AC$3:$AC$4922)))+((T3<>"")*ISNUMBER(SEARCH("|"&T3&"|",'5_ACOMPANHAMENTO'!$AC$3:$AC$4922)))+((U3<>"")*ISNUMBER(SEARCH("|"&U3&"|",'5_ACOMPANHAMENTO'!$AC$3:$AC$4922)))+((V3<>"")*ISNUMBER(SEARCH("|"&V3&"|",'5_ACOMPANHAMENTO'!$AC$3:$AC$4922)))+((W3<>"")*ISNUMBER(SEARCH("|"&W3&"|",'5_ACOMPANHAMENTO'!$AC$3:$AC$4922)))+((X3<>"")*ISNUMBER(SEARCH("|"&X3&"|",'5_ACOMPANHAMENTO'!$AC$3:$AC$4922)))+((Y3<>"")*ISNUMBER(SEARCH("|"&Y3&"|",'5_ACOMPANHAMENTO'!$AC$3:$AC$4922)))+((Z3<>"")*ISNUMBER(SEARCH("|"&Z3&"|",'5_ACOMPANHAMENTO'!$AC$3:$AC$4922)))+((AA3<>"")*ISNUMBER(SEARCH("|"&AA3&"|",'5_ACOMPANHAMENTO'!$AC$3:$AC$4922)))+((AB3<>"")*ISNUMBER(SEARCH("|"&AB3&"|",'5_ACOMPANHAMENTO'!$AC$3:$AC$4922))))>0)),'5_ACOMPANHAMENTO'!$J$3:$J$4922),0)) | E3: =IF(G3=0,"FINALIZADO",IF(TODAY()>A3,"ATRASADO "&TODAY()-A3&" DIAS","ADIANTADO "&A3-TODAY()&" DIAS")) | F3: =IF(OR($B3="",$C3=""),"",IFERROR(SUMPRODUCT(--(('5_ACOMPANHAMENTO'!$AD$3:$AD$4922=TRIM($C3&""))*('5_ACOMPANHAMENTO'!$AC$3:$AC$4922<>"")*((((I3<>"")*ISNUMBER(SEARCH("|"&I3&"|",'5_ACOMPANHAMENTO'!$AC$3:$AC$4922)))+((J3<>"")*ISNUMBER(SEARCH("|"&J3&"|",'5_ACOMPANHAMENTO'!$AC$3:$AC$4922)))+((K3<>"")*ISNUMBER(SEARCH("|"&K3&"|",'5_ACOMPANHAMENTO'!$AC$3:$AC$4922)))+((L3<>"")*ISNUMBER(SEARCH("|"&L3&"|",'5_ACOMPANHAMENTO'!$AC$3:$AC$4922)))+((M3<>"")*ISNUMBER(SEARCH("|"&M3&"|",'5_ACOMPANHAMENTO'!$AC$3:$AC$4922)))+((N3<>"")*ISNUMBER(SEARCH("|"&N3&"|",'5_ACOMPANHAMENTO'!$AC$3:$AC$4922)))+((O3<>"")*ISNUMBER(SEARCH("|"&O3&"|",'5_ACOMPANHAMENTO'!$AC$3:$AC$4922)))+((P3<>"")*ISNUMBER(SEARCH("|"&P3&"|",'5_ACOMPANHAMENTO'!$AC$3:$AC$4922)))+((Q3<>"")*ISNUMBER(SEARCH("|"&Q3&"|",'5_ACOMPANHAMENTO'!$AC$3:$AC$4922)))+((R3<>"")*ISNUMBER(SEARCH("|"&R3&"|",'5_ACOMPANHAMENTO'!$AC$3:$AC$4922)))+((S3<>"")*ISNUMBER(SEARCH("|"&S3&"|",'5_ACOMPANHAMENTO'!$AC$3:$AC$4922)))+((T3<>"")*ISNUMBER(SEARCH("|"&T3&"|",'5_ACOMPANHAMENTO'!$AC$3:$AC$4922)))+((U3<>"")*ISNUMBER(SEARCH("|"&U3&"|",'5_ACOMPANHAMENTO'!$AC$3:$AC$4922)))+((V3<>"")*ISNUMBER(SEARCH("|"&V3&"|",'5_ACOMPANHAMENTO'!$AC$3:$AC$4922)))+((W3<>"")*ISNUMBER(SEARCH("|"&W3&"|",'5_ACOMPANHAMENTO'!$AC$3:$AC$4922)))+((X3<>"")*ISNUMBER(SEARCH("|"&X3&"|",'5_ACOMPANHAMENTO'!$AC$3:$AC$4922)))+((Y3<>"")*ISNUMBER(SEARCH("|"&Y3&"|",'5_ACOMPANHAMENTO'!$AC$3:$AC$4922)))+((Z3<>"")*ISNUMBER(SEARCH("|"&Z3&"|",'5_ACOMPANHAMENTO'!$AC$3:$AC$4922)))+((AA3<>"")*ISNUMBER(SEARCH("|"&AA3&"|",'5_ACOMPANHAMENTO'!$AC$3:$AC$4922)))+((AB3<>"")*ISNUMBER(SEARCH("|"&AB3&"|",'5_ACOMPANHAMENTO'!$AC$3:$AC$4922))))>0)),'5_ACOMPANHAMENTO'!$O$3:$O$4922),0)) | G3: =IF(OR($B3="",$C3=""),"",D3-F3) | H3: =IF(OR($B3="",$C3=""),"",TRIM($B3&"")&"|"&TRIM($C3&"")) | I3: =IF($B3="","",TRIM(MID(SUBSTITUTE(TRIM(SUBSTITUTE(SUBSTITUTE(SUBSTITUTE(SUBSTITUTE(SUBSTITUTE(SUBSTITUTE(SUBSTITUTE(SUBSTITUTE(SUBSTITUTE(SUBSTITUTE(SUBSTITUTE(SUBSTITUTE(SUBSTITUTE(SUBSTITUTE(TRIM($B3&""),CHAR(10)," "),CHAR(13)," "),"."," "),";"," "),","," "),"/"," "),"+"," "),"-"," ")," "," ")," "," ")," "," ")," "," ")," "," ")," "," "))," ",REPT(" ",99)),1,99))) | J3: =IF($B3="","",TRIM(MID(SUBSTITUTE(TRIM(SUBSTITUTE(SUBSTITUTE(SUBSTITUTE(SUBSTITUTE(SUBSTITUTE(SUBSTITUTE(SUBSTITUTE(SUBSTITUTE(SUBSTITUTE(SUBSTITUTE(SUBSTITUTE(SUBSTITUTE(SUBSTITUTE(SUBSTITUTE(TRIM($B3&""),CHAR(10)," "),CHAR(13)," "),"."," "),";"," "),","," "),"/"," "),"+"," "),"-"," ")," "," ")," "," ")," "," ")," "," ")," "," ")," "," "))," ",REPT(" ",99)),100,99))) | K3: =IF($B3="","",TRIM(MID(SUBSTITUTE(TRIM(SUBSTITUTE(SUBSTITUTE(SUBSTITUTE(SUBSTITUTE(SUBSTITUTE(SUBSTITUTE(SUBSTITUTE(SUBSTITUTE(SUBSTITUTE(SUBSTITUTE(SUBSTITUTE(SUBSTITUTE(SUBSTITUTE(SUBSTITUTE(TRIM($B3&""),CHAR(10)," "),CHAR(13)," "),"."," "),";"," "),","," "),"/"," "),"+"," "),"-"," ")," "," ")," "," ")," "," ")," "," ")," "," ")," "," "))," ",REPT(" ",99)),199,99))) | L3: =IF($B3="","",TRIM(MID(SUBSTITUTE(TRIM(SUBSTITUTE(SUBSTITUTE(SUBSTITUTE(SUBSTITUTE(SUBSTITUTE(SUBSTITUTE(SUBSTITUTE(SUBSTITUTE(SUBSTITUTE(SUBSTITUTE(SUBSTITUTE(SUBSTITUTE(SUBSTITUTE(SUBSTITUTE(TRIM($B3&""),CHAR(10)," "),CHAR(13)," "),"."," "),";"," "),","," "),"/"," "),"+"," "),"-"," ")," "," ")," "," ")," "," ")," "," ")," "," ")," "," "))," ",REPT(" ",99)),298,99))) | M3: =IF($B3="","",TRIM(MID(SUBSTITUTE(TRIM(SUBSTITUTE(SUBSTITUTE(SUBSTITUTE(SUBSTITUTE(SUBSTITUTE(SUBSTITUTE(SUBSTITUTE(SUBSTITUTE(SUBSTITUTE(SUBSTITUTE(SUBSTITUTE(SUBSTITUTE(SUBSTITUTE(SUBSTITUTE(TRIM($B3&""),CHAR(10)," "),CHAR(13)," "),"."," "),";"," "),","," "),"/"," "),"+"," "),"-"," ")," "," ")," "," ")," "," ")," "," ")," "," ")," "," "))," ",REPT(" ",99)),397,99))) | N3: =IF($B3="","",TRIM(MID(SUBSTITUTE(TRIM(SUBSTITUTE(SUBSTITUTE(SUBSTITUTE(SUBSTITUTE(SUBSTITUTE(SUBSTITUTE(SUBSTITUTE(SUBSTITUTE(SUBSTITUTE(SUBSTITUTE(SUBSTITUTE(SUBSTITUTE(SUBSTITUTE(SUBSTITUTE(TRIM($B3&""),CHAR(10)," "),CHAR(13)," "),"."," "),";"," "),","," "),"/"," "),"+"," "),"-"," ")," "," ")," "," ")," "," ")," "," ")," "," ")," "," "))," ",REPT(" ",99)),496,99))) | O3: =IF($B3="","",TRIM(MID(SUBSTITUTE(TRIM(SUBSTITUTE(SUBSTITUTE(SUBSTITUTE(SUBSTITUTE(SUBSTITUTE(SUBSTITUTE(SUBSTITUTE(SUBSTITUTE(SUBSTITUTE(SUBSTITUTE(SUBSTITUTE(SUBSTITUTE(SUBSTITUTE(SUBSTITUTE(TRIM($B3&""),CHAR(10)," "),CHAR(13)," "),"."," "),";"," "),","," "),"/"," "),"+"," "),"-"," ")," "," ")," "," ")," "," ")," "," ")," "," ")," "," "))," ",REPT(" ",99)),595,99))) | P3: =IF($B3="","",TRIM(MID(SUBSTITUTE(TRIM(SUBSTITUTE(SUBSTITUTE(SUBSTITUTE(SUBSTITUTE(SUBSTITUTE(SUBSTITUTE(SUBSTITUTE(SUBSTITUTE(SUBSTITUTE(SUBSTITUTE(SUBSTITUTE(SUBSTITUTE(SUBSTITUTE(SUBSTITUTE(TRIM($B3&""),CHAR(10)," "),CHAR(13)," "),"."," "),";"," "),","," "),"/"," "),"+"," "),"-"," ")," "," ")," "," ")," "," ")," "," ")," "," ")," "," "))," ",REPT(" ",99)),694,99))) | Q3: =IF($B3="","",TRIM(MID(SUBSTITUTE(TRIM(SUBSTITUTE(SUBSTITUTE(SUBSTITUTE(SUBSTITUTE(SUBSTITUTE(SUBSTITUTE(SUBSTITUTE(SUBSTITUTE(SUBSTITUTE(SUBSTITUTE(SUBSTITUTE(SUBSTITUTE(SUBSTITUTE(SUBSTITUTE(TRIM($B3&""),CHAR(10)," "),CHAR(13)," "),"."," "),";"," "),","," "),"/"," "),"+"," "),"-"," ")," "," ")," "," ")," "," ")," "," ")," "," ")," "," "))," ",REPT(" ",99)),793,99))) | R3: =IF($B3="","",TRIM(MID(SUBSTITUTE(TRIM(SUBSTITUTE(SUBSTITUTE(SUBSTITUTE(SUBSTITUTE(SUBSTITUTE(SUBSTITUTE(SUBSTITUTE(SUBSTITUTE(SUBSTITUTE(SUBSTITUTE(SUBSTITUTE(SUBSTITUTE(SUBSTITUTE(SUBSTITUTE(TRIM($B3&""),CHAR(10)," "),CHAR(13)," "),"."," "),";"," "),","," "),"/"," "),"+"," "),"-"," ")," "," ")," "," ")," "," ")," "," ")," "," ")," "," "))," ",REPT(" ",99)),892,99))) | S3: =IF($B3="","",TRIM(MID(SUBSTITUTE(TRIM(SUBSTITUTE(SUBSTITUTE(SUBSTITUTE(SUBSTITUTE(SUBSTITUTE(SUBSTITUTE(SUBSTITUTE(SUBSTITUTE(SUBSTITUTE(SUBSTITUTE(SUBSTITUTE(SUBSTITUTE(SUBSTITUTE(SUBSTITUTE(TRIM($B3&""),CHAR(10)," "),CHAR(13)," "),"."," "),";"," "),","," "),"/"," "),"+"," "),"-"," ")," "," ")," "," ")," "," ")," "," ")," "," ")," "," "))," ",REPT(" ",99)),991,99))) | T3: =IF($B3="","",TRIM(MID(SUBSTITUTE(TRIM(SUBSTITUTE(SUBSTITUTE(SUBSTITUTE(SUBSTITUTE(SUBSTITUTE(SUBSTITUTE(SUBSTITUTE(SUBSTITUTE(SUBSTITUTE(SUBSTITUTE(SUBSTITUTE(SUBSTITUTE(SUBSTITUTE(SUBSTITUTE(TRIM($B3&""),CHAR(10)," "),CHAR(13)," "),"."," "),";"," "),","," "),"/"," "),"+"," "),"-"," ")," "," ")," "," ")," "," ")," "," ")," "," ")," "," "))," ",REPT(" ",99)),1090,99))) | U3: =IF($B3="","",TRIM(MID(SUBSTITUTE(TRIM(SUBSTITUTE(SUBSTITUTE(SUBSTITUTE(SUBSTITUTE(SUBSTITUTE(SUBSTITUTE(SUBSTITUTE(SUBSTITUTE(SUBSTITUTE(SUBSTITUTE(SUBSTITUTE(SUBSTITUTE(SUBSTITUTE(SUBSTITUTE(TRIM($B3&""),CHAR(10)," "),CHAR(13)," "),"."," "),";"," "),","," "),"/"," "),"+"," "),"-"," ")," "," ")," "," ")," "," ")," "," ")," "," ")," "," "))," ",REPT(" ",99)),1189,99))) | V3: =IF($B3="","",TRIM(MID(SUBSTITUTE(TRIM(SUBSTITUTE(SUBSTITUTE(SUBSTITUTE(SUBSTITUTE(SUBSTITUTE(SUBSTITUTE(SUBSTITUTE(SUBSTITUTE(SUBSTITUTE(SUBSTITUTE(SUBSTITUTE(SUBSTITUTE(SUBSTITUTE(SUBSTITUTE(TRIM($B3&""),CHAR(10)," "),CHAR(13)," "),"."," "),";"," "),","," "),"/"," "),"+"," "),"-"," ")," "," ")," "," ")," "," ")," "," ")," "," ")," "," "))," ",REPT(" ",99)),1288,99))) | W3: =IF($B3="","",TRIM(MID(SUBSTITUTE(TRIM(SUBSTITUTE(SUBSTITUTE(SUBSTITUTE(SUBSTITUTE(SUBSTITUTE(SUBSTITUTE(SUBSTITUTE(SUBSTITUTE(SUBSTITUTE(SUBSTITUTE(SUBSTITUTE(SUBSTITUTE(SUBSTITUTE(SUBSTITUTE(TRIM($B3&""),CHAR(10)," "),CHAR(13)," "),"."," "),";"," "),","," "),"/"," "),"+"," "),"-"," ")," "," ")," "," ")," "," ")," "," ")," "," ")," "," "))," ",REPT(" ",99)),1387,99))) | X3: =IF($B3="","",TRIM(MID(SUBSTITUTE(TRIM(SUBSTITUTE(SUBSTITUTE(SUBSTITUTE(SUBSTITUTE(SUBSTITUTE(SUBSTITUTE(SUBSTITUTE(SUBSTITUTE(SUBSTITUTE(SUBSTITUTE(SUBSTITUTE(SUBSTITUTE(SUBSTITUTE(SUBSTITUTE(TRIM($B3&""),CHAR(10)," "),CHAR(13)," "),"."," "),";"," "),","," "),"/"," "),"+"," "),"-"," ")," "," ")," "," ")," "," ")," "," ")," "," ")," "," "))," ",REPT(" ",99)),1486,99))) | Y3: =IF($B3="","",TRIM(MID(SUBSTITUTE(TRIM(SUBSTITUTE(SUBSTITUTE(SUBSTITUTE(SUBSTITUTE(SUBSTITUTE(SUBSTITUTE(SUBSTITUTE(SUBSTITUTE(SUBSTITUTE(SUBSTITUTE(SUBSTITUTE(SUBSTITUTE(SUBSTITUTE(SUBSTITUTE(TRIM($B3&""),CHAR(10)," "),CHAR(13)," "),"."," "),";"," "),","," "),"/"," "),"+"," "),"-"," ")," "," ")," "," ")," "," ")," "," ")," "," ")," "," "))," ",REPT(" ",99)),1585,99))) | Z3: =IF($B3="","",TRIM(MID(SUBSTITUTE(TRIM(SUBSTITUTE(SUBSTITUTE(SUBSTITUTE(SUBSTITUTE(SUBSTITUTE(SUBSTITUTE(SUBSTITUTE(SUBSTITUTE(SUBSTITUTE(SUBSTITUTE(SUBSTITUTE(SUBSTITUTE(SUBSTITUTE(SUBSTITUTE(TRIM($B3&""),CHAR(10)," "),CHAR(13)," "),"."," "),";"," "),","," "),"/"," "),"+"," "),"-"," ")," "," ")," "," ")," "," ")," "," ")," "," ")," "," "))," ",REPT(" ",99)),1684,99))) | AA3: =IF($B3="","",TRIM(MID(SUBSTITUTE(TRIM(SUBSTITUTE(SUBSTITUTE(SUBSTITUTE(SUBSTITUTE(SUBSTITUTE(SUBSTITUTE(SUBSTITUTE(SUBSTITUTE(SUBSTITUTE(SUBSTITUTE(SUBSTITUTE(SUBSTITUTE(SUBSTITUTE(SUBSTITUTE(TRIM($B3&""),CHAR(10)," "),CHAR(13)," "),"."," "),";"," "),","," "),"/"," "),"+"," "),"-"," ")," "," ")," "," ")," "," ")," "," ")," "," ")," "," "))," ",REPT(" ",99)),1783,99))) | AB3: =IF($B3="","",TRIM(MID(SUBSTITUTE(TRIM(SUBSTITUTE(SUBSTITUTE(SUBSTITUTE(SUBSTITUTE(SUBSTITUTE(SUBSTITUTE(SUBSTITUTE(SUBSTITUTE(SUBSTITUTE(SUBSTITUTE(SUBSTITUTE(SUBSTITUTE(SUBSTITUTE(SUBSTITUTE(TRIM($B3&""),CHAR(10)," "),CHAR(13)," "),"."," "),";"," "),","," "),"/"," "),"+"," "),"-"," ")," "," ")," "," ")," "," ")," "," ")," "," ")," "," "))," ",REPT(" ",99)),1882,99)))
A4: =IF(OR($B4="",$C4=""),"",IFERROR(INDEX('5_ACOMPANHAMENTO'!$A$3:$A$4922,MATCH(1,INDEX(('5_ACOMPANHAMENTO'!$AD$3:$AD$4922=TRIM($C4&""))*('5_ACOMPANHAMENTO'!$AC$3:$AC$4922<>"")*((((I4<>"")*ISNUMBER(SEARCH("|"&I4&"|",'5_ACOMPANHAMENTO'!$AC$3:$AC$4922)))+((J4<>"")*ISNUMBER(SEARCH("|"&J4&"|",'5_ACOMPANHAMENTO'!$AC$3:$AC$4922)))+((K4<>"")*ISNUMBER(SEARCH("|"&K4&"|",'5_ACOMPANHAMENTO'!$AC$3:$AC$4922)))+((L4<>"")*ISNUMBER(SEARCH("|"&L4&"|",'5_ACOMPANHAMENTO'!$AC$3:$AC$4922)))+((M4<>"")*ISNUMBER(SEARCH("|"&M4&"|",'5_ACOMPANHAMENTO'!$AC$3:$AC$4922)))+((N4<>"")*ISNUMBER(SEARCH("|"&N4&"|",'5_ACOMPANHAMENTO'!$AC$3:$AC$4922)))+((O4<>"")*ISNUMBER(SEARCH("|"&O4&"|",'5_ACOMPANHAMENTO'!$AC$3:$AC$4922)))+((P4<>"")*ISNUMBER(SEARCH("|"&P4&"|",'5_ACOMPANHAMENTO'!$AC$3:$AC$4922)))+((Q4<>"")*ISNUMBER(SEARCH("|"&Q4&"|",'5_ACOMPANHAMENTO'!$AC$3:$AC$4922)))+((R4<>"")*ISNUMBER(SEARCH("|"&R4&"|",'5_ACOMPANHAMENTO'!$AC$3:$AC$4922)))+((S4<>"")*ISNUMBER(SEARCH("|"&S4&"|",'5_ACOMPANHAMENTO'!$AC$3:$AC$4922)))+((T4<>"")*ISNUMBER(SEARCH("|"&T4&"|",'5_ACOMPANHAMENTO'!$AC$3:$AC$4922)))+((U4<>"")*ISNUMBER(SEARCH("|"&U4&"|",'5_ACOMPANHAMENTO'!$AC$3:$AC$4922)))+((V4<>"")*ISNUMBER(SEARCH("|"&V4&"|",'5_ACOMPANHAMENTO'!$AC$3:$AC$4922)))+((W4<>"")*ISNUMBER(SEARCH("|"&W4&"|",'5_ACOMPANHAMENTO'!$AC$3:$AC$4922)))+((X4<>"")*ISNUMBER(SEARCH("|"&X4&"|",'5_ACOMPANHAMENTO'!$AC$3:$AC$4922)))+((Y4<>"")*ISNUMBER(SEARCH("|"&Y4&"|",'5_ACOMPANHAMENTO'!$AC$3:$AC$4922)))+((Z4<>"")*ISNUMBER(SEARCH("|"&Z4&"|",'5_ACOMPANHAMENTO'!$AC$3:$AC$4922)))+((AA4<>"")*ISNUMBER(SEARCH("|"&AA4&"|",'5_ACOMPANHAMENTO'!$AC$3:$AC$4922)))+((AB4<>"")*ISNUMBER(SEARCH("|"&AB4&"|",'5_ACOMPANHAMENTO'!$AC$3:$AC$4922))))>0),0),0)),"")) | B4: 10176 | C4: SERRA FITA | D4: =IF(OR($B4="",$C4=""),"",IFERROR(SUMPRODUCT(--(('5_ACOMPANHAMENTO'!$AD$3:$AD$4922=TRIM($C4&""))*('5_ACOMPANHAMENTO'!$AC$3:$AC$4922<>"")*((((I4<>"")*ISNUMBER(SEARCH("|"&I4&"|",'5_ACOMPANHAMENTO'!$AC$3:$AC$4922)))+((J4<>"")*ISNUMBER(SEARCH("|"&J4&"|",'5_ACOMPANHAMENTO'!$AC$3:$AC$4922)))+((K4<>"")*ISNUMBER(SEARCH("|"&K4&"|",'5_ACOMPANHAMENTO'!$AC$3:$AC$4922)))+((L4<>"")*ISNUMBER(SEARCH("|"&L4&"|",'5_ACOMPANHAMENTO'!$AC$3:$AC$4922)))+((M4<>"")*ISNUMBER(SEARCH("|"&M4&"|",'5_ACOMPANHAMENTO'!$AC$3:$AC$4922)))+((N4<>"")*ISNUMBER(SEARCH("|"&N4&"|",'5_ACOMPANHAMENTO'!$AC$3:$AC$4922)))+((O4<>"")*ISNUMBER(SEARCH("|"&O4&"|",'5_ACOMPANHAMENTO'!$AC$3:$AC$4922)))+((P4<>"")*ISNUMBER(SEARCH("|"&P4&"|",'5_ACOMPANHAMENTO'!$AC$3:$AC$4922)))+((Q4<>"")*ISNUMBER(SEARCH("|"&Q4&"|",'5_ACOMPANHAMENTO'!$AC$3:$AC$4922)))+((R4<>"")*ISNUMBER(SEARCH("|"&R4&"|",'5_ACOMPANHAMENTO'!$AC$3:$AC$4922)))+((S4<>"")*ISNUMBER(SEARCH("|"&S4&"|",'5_ACOMPANHAMENTO'!$AC$3:$AC$4922)))+((T4<>"")*ISNUMBER(SEARCH("|"&T4&"|",'5_ACOMPANHAMENTO'!$AC$3:$AC$4922)))+((U4<>"")*ISNUMBER(SEARCH("|"&U4&"|",'5_ACOMPANHAMENTO'!$AC$3:$AC$4922)))+((V4<>"")*ISNUMBER(SEARCH("|"&V4&"|",'5_ACOMPANHAMENTO'!$AC$3:$AC$4922)))+((W4<>"")*ISNUMBER(SEARCH("|"&W4&"|",'5_ACOMPANHAMENTO'!$AC$3:$AC$4922)))+((X4<>"")*ISNUMBER(SEARCH("|"&X4&"|",'5_ACOMPANHAMENTO'!$AC$3:$AC$4922)))+((Y4<>"")*ISNUMBER(SEARCH("|"&Y4&"|",'5_ACOMPANHAMENTO'!$AC$3:$AC$4922)))+((Z4<>"")*ISNUMBER(SEARCH("|"&Z4&"|",'5_ACOMPANHAMENTO'!$AC$3:$AC$4922)))+((AA4<>"")*ISNUMBER(SEARCH("|"&AA4&"|",'5_ACOMPANHAMENTO'!$AC$3:$AC$4922)))+((AB4<>"")*ISNUMBER(SEARCH("|"&AB4&"|",'5_ACOMPANHAMENTO'!$AC$3:$AC$4922))))>0)),'5_ACOMPANHAMENTO'!$J$3:$J$4922),0)) | E4: =IF(G4=0,"FINALIZADO",IF(TODAY()>A4,"ATRASADO "&TODAY()-A4&" DIAS","ADIANTADO "&A4-TODAY()&" DIAS")) | F4: =IF(OR($B4="",$C4=""),"",IFERROR(SUMPRODUCT(--(('5_ACOMPANHAMENTO'!$AD$3:$AD$4922=TRIM($C4&""))*('5_ACOMPANHAMENTO'!$AC$3:$AC$4922<>"")*((((I4<>"")*ISNUMBER(SEARCH("|"&I4&"|",'5_ACOMPANHAMENTO'!$AC$3:$AC$4922)))+((J4<>"")*ISNUMBER(SEARCH("|"&J4&"|",'5_ACOMPANHAMENTO'!$AC$3:$AC$4922)))+((K4<>"")*ISNUMBER(SEARCH("|"&K4&"|",'5_ACOMPANHAMENTO'!$AC$3:$AC$4922)))+((L4<>"")*ISNUMBER(SEARCH("|"&L4&"|",'5_ACOMPANHAMENTO'!$AC$3:$AC$4922)))+((M4<>"")*ISNUMBER(SEARCH("|"&M4&"|",'5_ACOMPANHAMENTO'!$AC$3:$AC$4922)))+((N4<>"")*ISNUMBER(SEARCH("|"&N4&"|",'5_ACOMPANHAMENTO'!$AC$3:$AC$4922)))+((O4<>"")*ISNUMBER(SEARCH("|"&O4&"|",'5_ACOMPANHAMENTO'!$AC$3:$AC$4922)))+((P4<>"")*ISNUMBER(SEARCH("|"&P4&"|",'5_ACOMPANHAMENTO'!$AC$3:$AC$4922)))+((Q4<>"")*ISNUMBER(SEARCH("|"&Q4&"|",'5_ACOMPANHAMENTO'!$AC$3:$AC$4922)))+((R4<>"")*ISNUMBER(SEARCH("|"&R4&"|",'5_ACOMPANHAMENTO'!$AC$3:$AC$4922)))+((S4<>"")*ISNUMBER(SEARCH("|"&S4&"|",'5_ACOMPANHAMENTO'!$AC$3:$AC$4922)))+((T4<>"")*ISNUMBER(SEARCH("|"&T4&"|",'5_ACOMPANHAMENTO'!$AC$3:$AC$4922)))+((U4<>"")*ISNUMBER(SEARCH("|"&U4&"|",'5_ACOMPANHAMENTO'!$AC$3:$AC$4922)))+((V4<>"")*ISNUMBER(SEARCH("|"&V4&"|",'5_ACOMPANHAMENTO'!$AC$3:$AC$4922)))+((W4<>"")*ISNUMBER(SEARCH("|"&W4&"|",'5_ACOMPANHAMENTO'!$AC$3:$AC$4922)))+((X4<>"")*ISNUMBER(SEARCH("|"&X4&"|",'5_ACOMPANHAMENTO'!$AC$3:$AC$4922)))+((Y4<>"")*ISNUMBER(SEARCH("|"&Y4&"|",'5_ACOMPANHAMENTO'!$AC$3:$AC$4922)))+((Z4<>"")*ISNUMBER(SEARCH("|"&Z4&"|",'5_ACOMPANHAMENTO'!$AC$3:$AC$4922)))+((AA4<>"")*ISNUMBER(SEARCH("|"&AA4&"|",'5_ACOMPANHAMENTO'!$AC$3:$AC$4922)))+((AB4<>"")*ISNUMBER(SEARCH("|"&AB4&"|",'5_ACOMPANHAMENTO'!$AC$3:$AC$4922))))>0)),'5_ACOMPANHAMENTO'!$O$3:$O$4922),0)) | G4: =IF(OR($B4="",$C4=""),"",D4-F4) | H4: =IF(OR($B4="",$C4=""),"",TRIM($B4&"")&"|"&TRIM($C4&"")) | I4: =IF($B4="","",TRIM(MID(SUBSTITUTE(TRIM(SUBSTITUTE(SUBSTITUTE(SUBSTITUTE(SUBSTITUTE(SUBSTITUTE(SUBSTITUTE(SUBSTITUTE(SUBSTITUTE(SUBSTITUTE(SUBSTITUTE(SUBSTITUTE(SUBSTITUTE(SUBSTITUTE(SUBSTITUTE(TRIM($B4&""),CHAR(10)," "),CHAR(13)," "),"."," "),";"," "),","," "),"/"," "),"+"," "),"-"," ")," "," ")," "," ")," "," ")," "," ")," "," ")," "," "))," ",REPT(" ",99)),1,99))) | J4: =IF($B4="","",TRIM(MID(SUBSTITUTE(TRIM(SUBSTITUTE(SUBSTITUTE(SUBSTITUTE(SUBSTITUTE(SUBSTITUTE(SUBSTITUTE(SUBSTITUTE(SUBSTITUTE(SUBSTITUTE(SUBSTITUTE(SUBSTITUTE(SUBSTITUTE(SUBSTITUTE(SUBSTITUTE(TRIM($B4&""),CHAR(10)," "),CHAR(13)," "),"."," "),";"," "),","," "),"/"," "),"+"," "),"-"," ")," "," ")," "," ")," "," ")," "," ")," "," ")," "," "))," ",REPT(" ",99)),100,99))) | K4: =IF($B4="","",TRIM(MID(SUBSTITUTE(TRIM(SUBSTITUTE(SUBSTITUTE(SUBSTITUTE(SUBSTITUTE(SUBSTITUTE(SUBSTITUTE(SUBSTITUTE(SUBSTITUTE(SUBSTITUTE(SUBSTITUTE(SUBSTITUTE(SUBSTITUTE(SUBSTITUTE(SUBSTITUTE(TRIM($B4&""),CHAR(10)," "),CHAR(13)," "),"."," "),";"," "),","," "),"/"," "),"+"," "),"-"," ")," "," ")," "," ")," "," ")," "," ")," "," ")," "," "))," ",REPT(" ",99)),199,99))) | L4: =IF($B4="","",TRIM(MID(SUBSTITUTE(TRIM(SUBSTITUTE(SUBSTITUTE(SUBSTITUTE(SUBSTITUTE(SUBSTITUTE(SUBSTITUTE(SUBSTITUTE(SUBSTITUTE(SUBSTITUTE(SUBSTITUTE(SUBSTITUTE(SUBSTITUTE(SUBSTITUTE(SUBSTITUTE(TRIM($B4&""),CHAR(10)," "),CHAR(13)," "),"."," "),";"," "),","," "),"/"," "),"+"," "),"-"," ")," "," ")," "," ")," "," ")," "," ")," "," ")," "," "))," ",REPT(" ",99)),298,99))) | M4: =IF($B4="","",TRIM(MID(SUBSTITUTE(TRIM(SUBSTITUTE(SUBSTITUTE(SUBSTITUTE(SUBSTITUTE(SUBSTITUTE(SUBSTITUTE(SUBSTITUTE(SUBSTITUTE(SUBSTITUTE(SUBSTITUTE(SUBSTITUTE(SUBSTITUTE(SUBSTITUTE(SUBSTITUTE(TRIM($B4&""),CHAR(10)," "),CHAR(13)," "),"."," "),";"," "),","," "),"/"," "),"+"," "),"-"," ")," "," ")," "," ")," "," ")," "," ")," "," ")," "," "))," ",REPT(" ",99)),397,99))) | N4: =IF($B4="","",TRIM(MID(SUBSTITUTE(TRIM(SUBSTITUTE(SUBSTITUTE(SUBSTITUTE(SUBSTITUTE(SUBSTITUTE(SUBSTITUTE(SUBSTITUTE(SUBSTITUTE(SUBSTITUTE(SUBSTITUTE(SUBSTITUTE(SUBSTITUTE(SUBSTITUTE(SUBSTITUTE(TRIM($B4&""),CHAR(10)," "),CHAR(13)," "),"."," "),";"," "),","," "),"/"," "),"+"," "),"-"," ")," "," ")," "," ")," "," ")," "," ")," "," ")," "," "))," ",REPT(" ",99)),496,99))) | O4: =IF($B4="","",TRIM(MID(SUBSTITUTE(TRIM(SUBSTITUTE(SUBSTITUTE(SUBSTITUTE(SUBSTITUTE(SUBSTITUTE(SUBSTITUTE(SUBSTITUTE(SUBSTITUTE(SUBSTITUTE(SUBSTITUTE(SUBSTITUTE(SUBSTITUTE(SUBSTITUTE(SUBSTITUTE(TRIM($B4&""),CHAR(10)," "),CHAR(13)," "),"."," "),";"," "),","," "),"/"," "),"+"," "),"-"," ")," "," ")," "," ")," "," ")," "," ")," "," ")," "," "))," ",REPT(" ",99)),595,99))) | P4: =IF($B4="","",TRIM(MID(SUBSTITUTE(TRIM(SUBSTITUTE(SUBSTITUTE(SUBSTITUTE(SUBSTITUTE(SUBSTITUTE(SUBSTITUTE(SUBSTITUTE(SUBSTITUTE(SUBSTITUTE(SUBSTITUTE(SUBSTITUTE(SUBSTITUTE(SUBSTITUTE(SUBSTITUTE(TRIM($B4&""),CHAR(10)," "),CHAR(13)," "),"."," "),";"," "),","," "),"/"," "),"+"," "),"-"," ")," "," ")," "," ")," "," ")," "," ")," "," ")," "," "))," ",REPT(" ",99)),694,99))) | Q4: =IF($B4="","",TRIM(MID(SUBSTITUTE(TRIM(SUBSTITUTE(SUBSTITUTE(SUBSTITUTE(SUBSTITUTE(SUBSTITUTE(SUBSTITUTE(SUBSTITUTE(SUBSTITUTE(SUBSTITUTE(SUBSTITUTE(SUBSTITUTE(SUBSTITUTE(SUBSTITUTE(SUBSTITUTE(TRIM($B4&""),CHAR(10)," "),CHAR(13)," "),"."," "),";"," "),","," "),"/"," "),"+"," "),"-"," ")," "," ")," "," ")," "," ")," "," ")," "," ")," "," "))," ",REPT(" ",99)),793,99))) | R4: =IF($B4="","",TRIM(MID(SUBSTITUTE(TRIM(SUBSTITUTE(SUBSTITUTE(SUBSTITUTE(SUBSTITUTE(SUBSTITUTE(SUBSTITUTE(SUBSTITUTE(SUBSTITUTE(SUBSTITUTE(SUBSTITUTE(SUBSTITUTE(SUBSTITUTE(SUBSTITUTE(SUBSTITUTE(TRIM($B4&""),CHAR(10)," "),CHAR(13)," "),"."," "),";"," "),","," "),"/"," "),"+"," "),"-"," ")," "," ")," "," ")," "," ")," "," ")," "," ")," "," "))," ",REPT(" ",99)),892,99))) | S4: =IF($B4="","",TRIM(MID(SUBSTITUTE(TRIM(SUBSTITUTE(SUBSTITUTE(SUBSTITUTE(SUBSTITUTE(SUBSTITUTE(SUBSTITUTE(SUBSTITUTE(SUBSTITUTE(SUBSTITUTE(SUBSTITUTE(SUBSTITUTE(SUBSTITUTE(SUBSTITUTE(SUBSTITUTE(TRIM($B4&""),CHAR(10)," "),CHAR(13)," "),"."," "),";"," "),","," "),"/"," "),"+"," "),"-"," ")," "," ")," "," ")," "," ")," "," ")," "," ")," "," "))," ",REPT(" ",99)),991,99))) | T4: =IF($B4="","",TRIM(MID(SUBSTITUTE(TRIM(SUBSTITUTE(SUBSTITUTE(SUBSTITUTE(SUBSTITUTE(SUBSTITUTE(SUBSTITUTE(SUBSTITUTE(SUBSTITUTE(SUBSTITUTE(SUBSTITUTE(SUBSTITUTE(SUBSTITUTE(SUBSTITUTE(SUBSTITUTE(TRIM($B4&""),CHAR(10)," "),CHAR(13)," "),"."," "),";"," "),","," "),"/"," "),"+"," "),"-"," ")," "," ")," "," ")," "," ")," "," ")," "," ")," "," "))," ",REPT(" ",99)),1090,99))) | U4: =IF($B4="","",TRIM(MID(SUBSTITUTE(TRIM(SUBSTITUTE(SUBSTITUTE(SUBSTITUTE(SUBSTITUTE(SUBSTITUTE(SUBSTITUTE(SUBSTITUTE(SUBSTITUTE(SUBSTITUTE(SUBSTITUTE(SUBSTITUTE(SUBSTITUTE(SUBSTITUTE(SUBSTITUTE(TRIM($B4&""),CHAR(10)," "),CHAR(13)," "),"."," "),";"," "),","," "),"/"," "),"+"," "),"-"," ")," "," ")," "," ")," "," ")," "," ")," "," ")," "," "))," ",REPT(" ",99)),1189,99))) | V4: =IF($B4="","",TRIM(MID(SUBSTITUTE(TRIM(SUBSTITUTE(SUBSTITUTE(SUBSTITUTE(SUBSTITUTE(SUBSTITUTE(SUBSTITUTE(SUBSTITUTE(SUBSTITUTE(SUBSTITUTE(SUBSTITUTE(SUBSTITUTE(SUBSTITUTE(SUBSTITUTE(SUBSTITUTE(TRIM($B4&""),CHAR(10)," "),CHAR(13)," "),"."," "),";"," "),","," "),"/"," "),"+"," "),"-"," ")," "," ")," "," ")," "," ")," "," ")," "," ")," "," "))," ",REPT(" ",99)),1288,99))) | W4: =IF($B4="","",TRIM(MID(SUBSTITUTE(TRIM(SUBSTITUTE(SUBSTITUTE(SUBSTITUTE(SUBSTITUTE(SUBSTITUTE(SUBSTITUTE(SUBSTITUTE(SUBSTITUTE(SUBSTITUTE(SUBSTITUTE(SUBSTITUTE(SUBSTITUTE(SUBSTITUTE(SUBSTITUTE(TRIM($B4&""),CHAR(10)," "),CHAR(13)," "),"."," "),";"," "),","," "),"/"," "),"+"," "),"-"," ")," "," ")," "," ")," "," ")," "," ")," "," ")," "," "))," ",REPT(" ",99)),1387,99))) | X4: =IF($B4="","",TRIM(MID(SUBSTITUTE(TRIM(SUBSTITUTE(SUBSTITUTE(SUBSTITUTE(SUBSTITUTE(SUBSTITUTE(SUBSTITUTE(SUBSTITUTE(SUBSTITUTE(SUBSTITUTE(SUBSTITUTE(SUBSTITUTE(SUBSTITUTE(SUBSTITUTE(SUBSTITUTE(TRIM($B4&""),CHAR(10)," "),CHAR(13)," "),"."," "),";"," "),","," "),"/"," "),"+"," "),"-"," ")," "," ")," "," ")," "," ")," "," ")," "," ")," "," "))," ",REPT(" ",99)),1486,99))) | Y4: =IF($B4="","",TRIM(MID(SUBSTITUTE(TRIM(SUBSTITUTE(SUBSTITUTE(SUBSTITUTE(SUBSTITUTE(SUBSTITUTE(SUBSTITUTE(SUBSTITUTE(SUBSTITUTE(SUBSTITUTE(SUBSTITUTE(SUBSTITUTE(SUBSTITUTE(SUBSTITUTE(SUBSTITUTE(TRIM($B4&""),CHAR(10)," "),CHAR(13)," "),"."," "),";"," "),","," "),"/"," "),"+"," "),"-"," ")," "," ")," "," ")," "," ")," "," ")," "," ")," "," "))," ",REPT(" ",99)),1585,99))) | Z4: =IF($B4="","",TRIM(MID(SUBSTITUTE(TRIM(SUBSTITUTE(SUBSTITUTE(SUBSTITUTE(SUBSTITUTE(SUBSTITUTE(SUBSTITUTE(SUBSTITUTE(SUBSTITUTE(SUBSTITUTE(SUBSTITUTE(SUBSTITUTE(SUBSTITUTE(SUBSTITUTE(SUBSTITUTE(TRIM($B4&""),CHAR(10)," "),CHAR(13)," "),"."," "),";"," "),","," "),"/"," "),"+"," "),"-"," ")," "," ")," "," ")," "," ")," "," ")," "," ")," "," "))," ",REPT(" ",99)),1684,99))) | AA4: =IF($B4="","",TRIM(MID(SUBSTITUTE(TRIM(SUBSTITUTE(SUBSTITUTE(SUBSTITUTE(SUBSTITUTE(SUBSTITUTE(SUBSTITUTE(SUBSTITUTE(SUBSTITUTE(SUBSTITUTE(SUBSTITUTE(SUBSTITUTE(SUBSTITUTE(SUBSTITUTE(SUBSTITUTE(TRIM($B4&""),CHAR(10)," "),CHAR(13)," "),"."," "),";"," "),","," "),"/"," "),"+"," "),"-"," ")," "," ")," "," ")," "," ")," "," ")," "," ")," "," "))," ",REPT(" ",99)),1783,99))) | AB4: =IF($B4="","",TRIM(MID(SUBSTITUTE(TRIM(SUBSTITUTE(SUBSTITUTE(SUBSTITUTE(SUBSTITUTE(SUBSTITUTE(SUBSTITUTE(SUBSTITUTE(SUBSTITUTE(SUBSTITUTE(SUBSTITUTE(SUBSTITUTE(SUBSTITUTE(SUBSTITUTE(SUBSTITUTE(TRIM($B4&""),CHAR(10)," "),CHAR(13)," "),"."," "),";"," "),","," "),"/"," "),"+"," "),"-"," ")," "," ")," "," ")," "," ")," "," ")," "," ")," "," "))," ",REPT(" ",99)),1882,99)))
